<?xml version="1.0" ?>
<!-- =================================================================================== -->
<!-- |    This document was autogenerated by xacro from /home/jetson/Desktop/ARM/src/thth0110/urdf/thth0110.xacro | -->
<!-- |    EDITING THIS FILE BY HAND IS NOT RECOMMENDED                                 | -->
<!-- =================================================================================== -->
<robot name="thth0110">
    <link name="world" />
    <joint name="j0" type="fixed">
        <parent link="world" />
        <child link="base_link" />
    </joint>
    <link name="base_link">
        <inertial>
            <origin rpy="0 0 0" xyz="-9.46481603199267E-05 0.0581654269418611 0.04866865025217" />
            <mass value="0.30035406959819" />
            <inertia ixx="0.00027069543316674" ixy="-2.13815344801898E-07" ixz="7.07320383078014E-09" iyy="0.000180015863465612" iyz="1.47709366545211E-08" izz="0.00044068462099837" />
        </inertial>
        <visual>
            <origin rpy="0 0 0" xyz="0 0 0" />
            <geometry>
                <mesh filename="package://thth0110/meshes/base_link.STL" />
            </geometry>
            <material name="">
                <color rgba="0.792156862745098 0.819607843137255 0.933333333333333 1" />
            </material>
        </visual>
        <collision>
            <origin rpy="0 0 0" xyz="0 0 0" />
            <geometry>
                <mesh filename="package://thth0110/meshes/base_link.STL" />
            </geometry>
        </collision>
    </link>
    <link name="Empty_Link1">
        <inertial>
            <origin rpy="0 0 0" xyz="-0.0151750859915656 -0.00399245087056707 0.0561378060251985" />
            <mass value="0.549765707356901" />
            <inertia ixx="0.000475686533877782" ixy="4.1625850388632E-06" ixz="-1.43763812892749E-05" iyy="0.000315008917686389" iyz="-3.03828695806303E-06" izz="0.00049992188258295" />
        </inertial>
        <visual>
            <origin rpy="0 0 0" xyz="0 0 0" />
            <geometry>
                <mesh filename="package://thth0110/meshes/Empty_Link1.STL" />
            </geometry>
            <material name="">
                <color rgba="0.792156862745098 0.819607843137255 0.933333333333333 1" />
            </material>
        </visual>
        <collision>
            <origin rpy="0 0 0" xyz="0 0 0" />
            <geometry>
                <mesh filename="package://thth0110/meshes/Empty_Link1.STL" />
            </geometry>
        </collision>
    </link>
    <joint name="j1" type="revolute">
        <origin rpy="0 0 0" xyz="-0.0001 0.12404 0.0795" />
        <parent link="base_link" />
        <child link="Empty_Link1" />
        <axis xyz="0 0 1" />
        <limit effort="100" lower="-3.14" upper="3.14" velocity="10" />
    </joint>
    <link name="Empty_Link2">
        <inertial>
            <origin rpy="0 0 0" xyz="0.0189640183838487 -0.107927238111461 0.0616640229334262" />
            <mass value="0.325957208001636" />
            <inertia ixx="0.00154083690657679" ixy="0.000118838442663819" ixz="-6.20108037638599E-05" iyy="0.000441338792782083" iyz="0.000580352445944335" izz="0.0011342341701306" />
        </inertial>
        <visual>
            <origin rpy="0 0 0" xyz="0 0 0" />
            <geometry>
                <mesh filename="package://thth0110/meshes/Empty_Link2.STL" />
            </geometry>
            <material name="">
                <color rgba="0.792156862745098 0.819607843137255 0.933333333333333 1" />
            </material>
        </visual>
        <collision>
            <origin rpy="0 0 0" xyz="0 0 0" />
            <geometry>
                <mesh filename="package://thth0110/meshes/Empty_Link2.STL" />
            </geometry>
        </collision>
    </link>
    <joint name="j2" type="revolute">
        <origin rpy="0 0 0" xyz="0.052203 0.0055779 0.081" />
        <parent link="Empty_Link1" />
        <child link="Empty_Link2" />
        <axis xyz="0.99434 0.10625 0" />
        <limit effort="100" lower="-3.14" upper="3.14" velocity="10" />
    </joint>
    <link name="Empty_Link3">
        <inertial>
            <origin rpy="0 0 0" xyz="-0.0381933280232553 0.0584487347507447 0.00319379905981657" />
            <mass value="0.372416168853818" />
            <inertia ixx="0.000391637390148341" ixy="1.09586593948885E-05" ixz="-4.5179442129007E-07" iyy="0.000290989542029812" iyz="1.79039949299278E-06" izz="0.000251090686082734" />
        </inertial>
        <visual>
            <origin rpy="0 0 0" xyz="0 0 0" />
            <geometry>
                <mesh filename="package://thth0110/meshes/Empty_Link3.STL" />
            </geometry>
            <material name="">
                <color rgba="0.792156862745098 0.819607843137255 0.933333333333333 1" />
            </material>
        </visual>
        <collision>
            <origin rpy="0 0 0" xyz="0 0 0" />
            <geometry>
                <mesh filename="package://thth0110/meshes/Empty_Link3.STL" />
            </geometry>
        </collision>
    </link>
    <joint name="j3" type="revolute">
        <origin rpy="0 0 0" xyz="0.024986 -0.23384 0.13264" />
        <parent link="Empty_Link2" />
        <child link="Empty_Link3" />
        <axis xyz="0.99434 0.10625 0" />
        <limit effort="100" lower="-3.14" upper="3.14" velocity="10" />
    </joint>
    <link name="Empty_Link4">
        <inertial>
            <origin rpy="0 0 0" xyz="-0.0154333677247912 0.14374505039843 0.00674813689898141" />
            <mass value="0.34066787706499" />
            <inertia ixx="0.000318598903007456" ixy="2.20601818971233E-05" ixz="1.32285615494824E-06" iyy="0.000122801247546674" iyz="-1.0991461247757E-05" izz="0.000332684335927319" />
        </inertial>
        <visual>
            <origin rpy="0 0 0" xyz="0 0 0" />
            <geometry>
                <mesh filename="package://thth0110/meshes/Empty_Link4.STL" />
            </geometry>
            <material name="">
                <color rgba="0.792156862745098 0.819607843137255 0.933333333333333 1" />
            </material>
        </visual>
        <collision>
            <origin rpy="0 0 0" xyz="0 0 0" />
            <geometry>
                <mesh filename="package://thth0110/meshes/Empty_Link4.STL" />
            </geometry>
        </collision>
    </link>
    <joint name="j4" type="revolute">
        <origin rpy="0 0 0" xyz="-0.03989 0.079198 0.0043217" />
        <parent link="Empty_Link3" />
        <child link="Empty_Link4" />
        <axis xyz="0.1061 -0.99299 -0.052006" />
        <limit effort="100" lower="-3.14" upper="3.14" velocity="10" />
    </joint>
    <link name="Empty_Link5">
        <inertial>
            <origin rpy="0 0 0" xyz="0.0231359607951343 0.0491399156551176 0.0483942593470714" />
            <mass value="0.23163739781675" />
            <inertia ixx="0.000210954688882632" ixy="-3.6535945786043E-05" ixz="-1.66433364641079E-06" iyy="0.000141806822397899" iyz="-7.03169835125346E-06" izz="0.000281867036595184" />
        </inertial>
        <visual>
            <origin rpy="0 0 0" xyz="0 0 0" />
            <geometry>
                <mesh filename="package://thth0110/meshes/Empty_Link5.STL" />
            </geometry>
            <material name="">
                <color rgba="0.792156862745098 0.819607843137255 0.933333333333333 1" />
            </material>
        </visual>
        <collision>
            <origin rpy="0 0 0" xyz="0 0 0" />
            <geometry>
                <mesh filename="package://thth0110/meshes/Empty_Link5.STL" />
            </geometry>
        </collision>
    </link>
    <joint name="j5" type="revolute">
        <origin rpy="0 0 0" xyz="-0.02458 0.23003 -0.013938" />
        <parent link="Empty_Link4" />
        <child link="Empty_Link5" />
        <axis xyz="0.0055254 -0.051712 0.99865" />
        <limit effort="100" lower="-3.14" upper="3.14" velocity="10" />
    </joint>
    <link name="camera_Link">
        <inertial>
            <origin rpy="0 0 0" xyz="0.0106700250722204 -0.00440418433698633 0.000530626053692917" />
            <mass value="0.0375088017012115" />
            <inertia ixx="1.94914210099807E-05" ixy="-8.04429593621107E-06" ixz="-1.85033895526069E-07" iyy="5.83588679302749E-06" iyz="-5.07127364470073E-07" izz="2.19002696899909E-05" />
        </inertial>
        <visual>
            <origin rpy="0 0 0" xyz="0 0 0" />
            <geometry>
                <mesh filename="package://thth0110/meshes/camera_Link.STL" />
            </geometry>
            <material name="">
                <color rgba="0.792156862745098 0.819607843137255 0.933333333333333 1" />
            </material>
        </visual>
        <collision>
            <origin rpy="0 0 0" xyz="0 0 0" />
            <geometry>
                <mesh filename="package://thth0110/meshes/camera_Link.STL" />
            </geometry>
        </collision>
    </link>
    <joint name="j_camera" type="fixed">
        <origin rpy="0 0 1.5708" xyz="0.062522 0.13601 0.11875" />
        <parent link="Empty_Link5" />
        <child link="camera_Link" />
        <axis xyz="0 0 0" />
    </joint>
    <link name="Empty_Link6">
        <inertial>
            <origin rpy="0 0 0" xyz="0.00804624017095822 0.0172072554925143 0.0138462486673112" />
            <mass value="0.0803751499998822" />
            <inertia ixx="1.44670093386749E-05" ixy="3.55129167972648E-06" ixz="1.17738318901375E-07" iyy="2.09529105725378E-05" iyz="2.29151889595778E-07" izz="1.6672704802587E-05" />
        </inertial>
        <visual>
            <origin rpy="0 0 0" xyz="0 0 0" />
            <geometry>
                <mesh filename="package://thth0110/meshes/Empty_Link6.STL" />
            </geometry>
            <material name="">
                <color rgba="0.792156862745098 0.819607843137255 0.933333333333333 1" />
            </material>
        </visual>
        <collision>
            <origin rpy="0 0 0" xyz="0 0 0" />
            <geometry>
                <mesh filename="package://thth0110/meshes/Empty_Link6.STL" />
            </geometry>
        </collision>
    </link>
    <joint name="j6" type="prismatic">
        <origin rpy="0 0 0" xyz="0.019598 0.042485 0.028077" />
        <parent link="Empty_Link5" />
        <child link="Empty_Link6" />
        <axis xyz="0.40528 0.91308 0.045039" />
        <limit effort="100" lower="0" upper="0.1" velocity="0.01" />
    </joint>
    <link name="Empty_Link7">
        <inertial>
            <origin rpy="0 0 0" xyz="0.060959 0.13897 0.0076845" />
            <mass value="0.26037" />
            <inertia ixx="0.00022297" ixy="-4.6396E-05" ixz="-1.0121E-05" iyy="0.00013828" iyz="-4.3766E-06" izz="0.00018924" />
        </inertial>
        <visual>
            <origin rpy="0 0 0" xyz="0 0 0" />
            <geometry>
                <mesh filename="package://thth0110/meshes/Empty_Link7.STL" />
            </geometry>
            <material name="">
                <color rgba="0.79216 0.81961 0.93333 1" />
            </material>
        </visual>
        <collision>
            <origin rpy="0 0 0" xyz="0 0 0" />
            <geometry>
                <mesh filename="package://thth0110/meshes/Empty_Link7.STL" />
            </geometry>
        </collision>
    </link>
    <joint name="j7" type="revolute">
        <origin rpy="0 0 0" xyz="0 0 0" />
        <parent link="Empty_Link6" />
        <child link="Empty_Link7" />
        <axis xyz="0.40528 0.91308 0.045039" />
        <limit effort="100" lower="-3.14" upper="3.14" velocity="10" />
    </joint>
    <link name="Empty_Link8">
        <inertial>
            <origin rpy="0 0 0" xyz="0.0097007 0.050032 -0.026523" />
            <mass value="0.11578" />
            <inertia ixx="0.00010505" ixy="-1.9951E-05" ixz="-6.9402E-07" iyy="5.504E-05" iyz="1.4536E-05" izz="0.00011524" />
        </inertial>
        <visual>
            <origin rpy="0 0 0" xyz="0 0 0" />
            <geometry>
                <mesh filename="package://thth0110/meshes/Empty_Link8.STL" />
            </geometry>
            <material name="">
                <color rgba="0.79216 0.81961 0.93333 1" />
            </material>
        </visual>
        <collision>
            <origin rpy="0 0 0" xyz="0 0 0" />
            <geometry>
                <mesh filename="package://thth0110/meshes/Empty_Link8.STL" />
            </geometry>
        </collision>
    </link>
    <joint name="j8" type="revolute">
        <origin rpy="0 0 0" xyz="0.091108 0.15115 -0.013476" />
        <parent link="Empty_Link7" />
        <child link="Empty_Link8" />
        <axis xyz="-0.91417 0.40449 0.026003" />
        <limit effort="100" lower="-3.14" upper="3.14" velocity="10" />
    </joint>
    <link name="Empty_Link9">
        <inertial>
            <origin rpy="0 0 0" xyz="-0.00893984042603618 0.048320629256864 0.0296874404855317" />
            <mass value="0.131989761107744" />
            <inertia ixx="0.000111060813609043" ixy="-2.07000854026729E-05" ixz="-3.6474244468331E-06" iyy="6.6480015232698E-05" iyz="-2.33141757887285E-05" izz="0.000114122417790849" />
        </inertial>
        <visual>
            <origin rpy="0 0 0" xyz="0 0 0" />
            <geometry>
                <mesh filename="package://thth0110/meshes/Empty_Link9.STL" />
            </geometry>
            <material name="">
                <color rgba="0.792156862745098 0.819607843137255 0.933333333333333 1" />
            </material>
        </visual>
        <collision>
            <origin rpy="0 0 0" xyz="0 0 0" />
            <geometry>
                <mesh filename="package://thth0110/meshes/Empty_Link9.STL" />
            </geometry>
        </collision>
    </link>
    <joint name="j9" type="revolute">
        <origin rpy="0 0 0" xyz="0.10608 0.14259 0.026824" />
        <parent link="Empty_Link7" />
        <child link="Empty_Link9" />
        <axis xyz="-0.91417 0.40449 0.026003" />
        <limit effort="100" lower="-3.14" upper="3.14" velocity="10" />
        <!-- 👇 关键：添加 mimic -->
        <mimic joint="j8" multiplier="-1.0" offset="0.0" />
    </joint>
    <transmission name="tran_j1">
        <!-- 关联关节名-传动名 -->
        <type>transmission_interface/SimpleTransmission</type>
        <!-- 简单传动 -->
        <joint name="j1">
            <hardwareInterface>hardware_interface/PositionJointInterface</hardwareInterface>
            <!-- 位置控制接口 -->
        </joint>
        <actuator name="motor_j1">
            <!-- 关联关节名-电机名 -->
            <hardwareInterface>hardware_interface/PositionJointInterface</hardwareInterface>
            <!-- 位置控制接口-必须保持一致 -->
            <mechanicalReduction>1</mechanicalReduction>
            <!-- 机械减速比-1表示无减速比 -->
        </actuator>
    </transmission>
    <transmission name="tran_j2">
        <!-- 关联关节名-传动名 -->
        <type>transmission_interface/SimpleTransmission</type>
        <!-- 简单传动 -->
        <joint name="j2">
            <hardwareInterface>hardware_interface/PositionJointInterface</hardwareInterface>
            <!-- 位置控制接口 -->
        </joint>
        <actuator name="motor_j2">
            <!-- 关联关节名-电机名 -->
            <hardwareInterface>hardware_interface/PositionJointInterface</hardwareInterface>
            <!-- 位置控制接口-必须保持一致 -->
            <mechanicalReduction>1</mechanicalReduction>
            <!-- 机械减速比-1表示无减速比 -->
        </actuator>
    </transmission>
    <transmission name="tran_j3">
        <!-- 关联关节名-传动名 -->
        <type>transmission_interface/SimpleTransmission</type>
        <!-- 简单传动 -->
        <joint name="j3">
            <hardwareInterface>hardware_interface/PositionJointInterface</hardwareInterface>
            <!-- 位置控制接口 -->
        </joint>
        <actuator name="motor_j3">
            <!-- 关联关节名-电机名 -->
            <hardwareInterface>hardware_interface/PositionJointInterface</hardwareInterface>
            <!-- 位置控制接口-必须保持一致 -->
            <mechanicalReduction>1</mechanicalReduction>
            <!-- 机械减速比-1表示无减速比 -->
        </actuator>
    </transmission>
    <transmission name="tran_j4">
        <!-- 关联关节名-传动名 -->
        <type>transmission_interface/SimpleTransmission</type>
        <!-- 简单传动 -->
        <joint name="j4">
            <hardwareInterface>hardware_interface/PositionJointInterface</hardwareInterface>
            <!-- 位置控制接口 -->
        </joint>
        <actuator name="motor_j4">
            <!-- 关联关节名-电机名 -->
            <hardwareInterface>hardware_interface/PositionJointInterface</hardwareInterface>
            <!-- 位置控制接口-必须保持一致 -->
            <mechanicalReduction>1</mechanicalReduction>
            <!-- 机械减速比-1表示无减速比 -->
        </actuator>
    </transmission>
    <transmission name="tran_j5">
        <!-- 关联关节名-传动名 -->
        <type>transmission_interface/SimpleTransmission</type>
        <!-- 简单传动 -->
        <joint name="j5">
            <hardwareInterface>hardware_interface/PositionJointInterface</hardwareInterface>
            <!-- 位置控制接口 -->
        </joint>
        <actuator name="motor_j5">
            <!-- 关联关节名-电机名 -->
            <hardwareInterface>hardware_interface/PositionJointInterface</hardwareInterface>
            <!-- 位置控制接口-必须保持一致 -->
            <mechanicalReduction>1</mechanicalReduction>
            <!-- 机械减速比-1表示无减速比 -->
        </actuator>
    </transmission>
    <transmission name="tran_j6">
        <!-- 关联关节名-传动名 -->
        <type>transmission_interface/SimpleTransmission</type>
        <!-- 简单传动 -->
        <joint name="j6">
            <hardwareInterface>hardware_interface/PositionJointInterface</hardwareInterface>
            <!-- 位置控制接口 -->
        </joint>
        <actuator name="motor_j6">
            <!-- 关联关节名-电机名 -->
            <hardwareInterface>hardware_interface/PositionJointInterface</hardwareInterface>
            <!-- 位置控制接口-必须保持一致 -->
            <mechanicalReduction>1</mechanicalReduction>
            <!-- 机械减速比-1表示无减速比 -->
        </actuator>
    </transmission>
    <transmission name="tran_j7">
        <!-- 关联关节名-传动名 -->
        <type>transmission_interface/SimpleTransmission</type>
        <!-- 简单传动 -->
        <joint name="j7">
            <hardwareInterface>hardware_interface/PositionJointInterface</hardwareInterface>
            <!-- 位置控制接口 -->
        </joint>
        <actuator name="motor_j7">
            <!-- 关联关节名-电机名 -->
            <hardwareInterface>hardware_interface/PositionJointInterface</hardwareInterface>
            <!-- 位置控制接口-必须保持一致 -->
            <mechanicalReduction>1</mechanicalReduction>
            <!-- 机械减速比-1表示无减速比 -->
        </actuator>
    </transmission>
    <transmission name="tran_j8">
        <!-- 关联关节名-传动名 -->
        <type>transmission_interface/SimpleTransmission</type>
        <!-- 简单传动 -->
        <joint name="j8">
            <hardwareInterface>hardware_interface/PositionJointInterface</hardwareInterface>
            <!-- 位置控制接口 -->
        </joint>
        <actuator name="motor_j8">
            <!-- 关联关节名-电机名 -->
            <hardwareInterface>hardware_interface/PositionJointInterface</hardwareInterface>
            <!-- 位置控制接口-必须保持一致 -->
            <mechanicalReduction>1</mechanicalReduction>
            <!-- 机械减速比-1表示无减速比 -->
        </actuator>
    </transmission>
    <!-- 夹爪主副 -->
    <!-- ros_control plugin -->
    <gazebo>
        <plugin filename="libgazebo_ros_control.so" name="gazebo_ros_control">
            <robotNamespace>/thth0110</robotNamespace>
            <robotSimType>gazebo_ros_control/DefaultRobotHWSim</robotSimType>
            <legacyModeNS>true</legacyModeNS>
        </plugin>
    </gazebo>
    <transmission name="trans_j9">
        <type>transmission_interface/SimpleTransmission</type>
        <joint name="j9">
            <hardwareInterface>hardware_interface/EffortJointInterface</hardwareInterface>
        </joint>
        <actuator name="j9_motor">
            <hardwareInterface>hardware_interface/EffortJointInterface</hardwareInterface>
            <mechanicalReduction>1</mechanicalReduction>
        </actuator>
    </transmission>
</robot>

